Workbook

Sheet PSV Tab
A1: First Name | B1: Middle Name | C1: Last Name | D1: EPDB PIN | E1: Provider Type | F1: Source Code | G1: Status Eff Date | H1: Maintained By | I1: Netid's | J1: License State | K1: LIC_TYPE_NM | L1: License ID | M1: LIC_EXPRTN_DT | N1: LIC_PRDEXPN_DT | O1: NPI_NO | P1: Service Location State | Q1: provider type
A2: Todd | B2: A | C2: Drexel | D2: 7049942 | E2: PH | F2: A | G2: 45947 | H2: AHP | I2: 187,1695,1717,4144,4148,8056,8186,8232,8232 | J2: KY | K2: STATE MEDICAL | L2: 03011 | M2: 2958465 | N2: 46081 | O2: 1437259108 | P2: AL,KY | Q2: =VLOOKUP(E30879,Sheet3!A:B,2,FALSE)
A3: Chris | B3: A. | C3: Covington | D3: 4663472 | E3: PH | F3: A | G3: 46073 | H3: AHP | I3: 511,1289,2249,2344,3262,3416,3779,3780,3781,3957,4144,4148,4632,4633,4634,4696 | J3: KY | K3: STATE MEDICAL | L3: 02403 | M3: 2958465 | N3: 46081 | O3: 1164916862 | P3: IL,KY,MI | Q3: =VLOOKUP(E11150,Sheet3!A:B,2,FALSE)
A4: Pooja | C4: Mody | D4: 6066380 | E4: PH | F4: A | G4: 45975 | H4: AHP | I4: 355,588,589,1345,1995,2158,2159,2408,3264,3417,3670,3671,8232 | J4: NV | K4: STATE MEDICAL | L4: DO3284 | M4: 2958465 | N4: 46022 | O4: 1962762997 | P4: AZ,NV | Q4: =VLOOKUP(E18918,Sheet3!A:B,2,FALSE)
A5: Jakob | B5: L | C5: Mauer | D5: 8505096 | E5: SW | F5: A | G5: 45933 | H5: ABH | I5: 1993,1995,2158,2159,2408,3670,3671,4328,4329,11306,11307,11308 | J5: NV | K5: OPERATING | L5: 10450-C | M5: 2958465 | N5: 46053 | O5: 1467027649 | P5: NV | Q5: =VLOOKUP(E42944,Sheet3!A:B,2,FALSE)
A6: Sarah | B6: Ellen | C6: Repp | D6: 6482998 | E6: PT | F6: A | G6: 46150 | H6: AHP | I6: 1995,2158,2159,2408,3670,3671 | J6: NV | K6: OPERATING | L6: 4001 | M6: 2958465 | N6: 46151 | O6: 1588122758 | P6: NV | Q6: =VLOOKUP(E23946,Sheet3!A:B,2,FALSE)
A7: Samantha | B7: Kaye | C7: Goodwin | D7: 8197657 | E7: SW | F7: A | G7: 45996 | H7: LLP | I7: 21,21,433,433,1737,1737,1954,3532,4144,4148 | J7: KY | K7: OPERATING | L7: 257688 | M7: 2958465 | N7: 46066 | O7: 1407502602 | P7: IN,KY | Q7: =VLOOKUP(E38514,Sheet3!A:B,2,FALSE)
A8: Michael | C8: Holland | D8: 4688662 | E8: PH | F8: A | G8: 46024 | H8: AHP | I8: 528,690,2326,4144,4148,9025,9027,9028,9029,9034,9035,9036,9087,9090,9169,13046,13047 | J8: KY | K8: STATE MEDICAL | L8: 05713 | M8: 2958465 | N8: 46081 | O8: 1538423561 | P8: KY,MO | Q8: =VLOOKUP(E11295,Sheet3!A:B,2,FALSE)
A9: Zachary | B9: Cole | C9: Dowell | D9: 8947730 | E9: DC | F9: A | G9: 45891 | H9: AHP | I9: 21,433,1737,1954,4144,4148 | J9: KY | K9: OPERATING | L9: 282712 | M9: 2958465 | N9: 46128 | O9: 1568175677 | P9: KY | Q9: =VLOOKUP(E49897,Sheet3!A:B,2,FALSE)
A10: Linzi | B10: G | C10: Antos | D10: 8295384 | E10: SW | F10: A | G10: 45940 | H10: ABH | I10: 511,1289,2249,2344,2772,2773,2774,3058 | J10: KY | K10: OPERATING | L10: 257741 | M10: 2958465 | N10: 46082 | O10: 1124672084 | P10: KY | Q10: =VLOOKUP(E39909,Sheet3!A:B,2,FALSE)
A11: Marivelle | C11: Nunez-Rucker | D11: 4737585 | E11: MT | F11: A | G11: 45933 | H11: ABH | I11: 1995,2158,2159,2408,3058 | J11: NV | K11: OPERATING | L11: 01306 | M11: 2958465 | N11: 46023 | O11: 1336480730 | P11: NV | Q11: =VLOOKUP(E11775,Sheet3!A:B,2,FALSE)
A12: Chase | C12: Beal | D12: 8133518 | E12: PH | F12: A | G12: 45877 | H12: AHP | I12: 1995,2158,2159,2408,3670,3671,8232 | J12: NV | K12: STATE MEDICAL | L12: DO3897 | M12: 2958465 | N12: 46021 | O12: 1548889983 | P12: NV | Q12: =VLOOKUP(E37629,Sheet3!A:B,2,FALSE)
A13: Amber | B13: P | C13: Poynter | D13: 8169438 | E13: ST | F13: A | G13: 45989 | H13: AHP | I13: 4144,4148,8232 | J13: KY | K13: OPERATING | L13: 278847 | M13: 2958465 | N13: 46083 | O13: 1912572629 | P13: KY | Q13: =VLOOKUP(E38060,Sheet3!A:B,2,FALSE)
A14: Jeremy | C14: Farmer | D14: 8695808 | E14: DC | F14: A | G14: 45884 | H14: AHP | I14: 4144,4148 | J14: KY | K14: OPERATING | L14: 300621 | M14: 2958465 | N14: 46128 | O14: 1922999036 | P14: KY | Q14: =VLOOKUP(E45818,Sheet3!A:B,2,FALSE)
A15: Michael | B15: C | C15: Hendrickson | D15: 8060731 | E15: PT | F15: A | G15: 46108 | H15: AHP | I15: 1993,4328,4329,11306,11307,11308 | J15: NV | K15: OPERATING | L15: 5171 | M15: 2958465 | N15: 46185 | O15: 1578244612 | P15: NV | Q15: =VLOOKUP(E36563,Sheet3!A:B,2,FALSE)
A16: Katherine | B16: Leann | C16: Tackett | D16: 6000098 | E16: PH | F16: A | G16: 46024 | H16: AHP | I16: 156,1557,1558,1559,4144,4148 | J16: KY | K16: STATE MEDICAL | L16: 04007 | M16: 2958465 | N16: 46081 | O16: 1992115562 | P16: KY | Q16: =VLOOKUP(E18120,Sheet3!A:B,2,FALSE)
A17: Lauren | C17: Blank | D17: 8419788 | E17: LPC | F17: A | G17: 45940 | H17: AHP | I17: 1995,2158,2159,2408,3058,8232,8335,9510,9511,9512 | J17: NV | K17: OPERATING | L17: CP5843 | M17: 2958465 | N17: 46023 | O17: 1891440442 | P17: NV | Q17: =VLOOKUP(E41842,Sheet3!A:B,2,FALSE)
A18: Gregory | B18: S. | C18: Thomas | D18: 7607778 | E18: DC | F18: A | G18: 45877 | H18: AHP | I18: 21,433,1737,1954 | J18: KY | K18: OPERATING | L18: 249593 | M18: 2958465 | N18: 46128 | O18: 1851310460 | P18: KY | Q18: =VLOOKUP(E33833,Sheet3!A:B,2,FALSE)
A19: Nawar | C19: Soda | D19: 9312409 | E19: PH | F19: A | G19: 46066 | H19: AHP | I19: 511,1289,2249,2344,4144,4148,8232 | J19: KY | K19: STATE MEDICAL | L19: 41992 | M19: 2958465 | N19: 46081 | O19: 1083812598 | P19: KY | Q19: =VLOOKUP(E52605,Sheet3!A:B,2,FALSE)
A20: Carl | C20: Seger | D20: 9420399 | E20: PH | F20: A | G20: 45919 | H20: AHP | I20: 74,101,209,226,244,257,511,1289,2089,2249,2344,3952,3953,3998,3999,4000,4144,4148,4159,4163,4222,8232 | J20: KY | K20: STATE MEDICAL | L20: 56216 | M20: 2958465 | N20: 46081 | O20: 1699957308 | P20: CA,CO,KY,OR | Q20: =VLOOKUP(E53298,Sheet3!A:B,2,FALSE)
A21: Katherine | C21: Hamilton | D21: 9179328 | E21: PAS | F21: A | G21: 45947 | H21: AHP | I21: 21,21,433,433,1737,1737,1954,1954,3532,4144,4145,4148,4149 | J21: KY | K21: OPERATING | L21: PA1022 | M21: 2958465 | N21: 46112 | O21: 1750369633 | P21: IN,KY | Q21: =VLOOKUP(E51780,Sheet3!A:B,2,FALSE)
A22: Kyung Hyun | C22: Lee | D22: 1295837 | E22: PH | F22: A | G22: 46003 | H22: AHP | I22: 1995,2158,2159,2408,3670,3671,8232 | J22: NV | K22: STATE MEDICAL | L22: DO3980 | M22: 2958465 | N22: 46022 | O22: 1679100739 | P22: NV | Q22: =VLOOKUP(E833,Sheet3!A:B,2,FALSE)
A23: Scott | C23: Moore | D23: 9600364 | E23: PH | F23: A | G23: 45884 | H23: AHP | I23: 156,1557,1558,1559,3418,4144,4148,8232 | J23: KY | K23: STATE MEDICAL | L23: 43859 | M23: 2958465 | N23: 46081 | O23: 1558414441 | P23: KY | Q23: =VLOOKUP(E54520,Sheet3!A:B,2,FALSE)
A24: Sherrie | B24: A. | C24: Shivok | D24: 6462493 | E24: LPC | F24: A | G24: 46143 | H24: ABH | I24: 24,64,72,128,138,140,214,243,408,486,557,558,562,563,564,638,1217,1300,1301,1339,1340,1341,1669,1979,1980,1981,1982,1983,1984,2151,2152,2153,2341,2342,2833,3058,3058,3532,3533,3534,3552,3553,3572,3610,4145,4149,8232,8232,9750 | J24: NV | K24: OPERATING | L24: CP5899-R | M24: 2958465 | N24: 46023 | O24: 1851865281 | P24: IN,PA | Q24: =VLOOKUP(E23705,Sheet3!A:B,2,FALSE)
A25: Nicole | C25: Safford | D25: 8773760 | E25: MT | F25: A | G25: 45863 | H25: ABH | I25: 1993,1995,2158,2159,2408,3058,3670,3671,4328,4329,11306,11307,11308 | J25: NV | K25: OPERATING | L25: MI4172 | M25: 2958465 | N25: 45993 | O25: 1093166936 | P25: NV | Q25: =VLOOKUP(E47006,Sheet3!A:B,2,FALSE)
A26: Gustavo | B26: Salathiel | C26: Reyes Sanchez | D26: 3789343 | E26: SW | F26: A | G26: 45926 | H26: ABH | I26: 1995,2158,2159,2408,3058,3670,3671 | J26: NV | K26: OPERATING | L26: 11294-M | M26: 2958465 | N26: 45991 | O26: 1679217921 | P26: NV | Q26: =VLOOKUP(E7930,Sheet3!A:B,2,FALSE)
A27: Milagros | C27: Severin-Ruiz | D27: 8290412 | E27: MT | F27: A | G27: 45919 | H27: AHP | I27: 1995,2158,2159,2408,3058,8232 | J27: NV | K27: OPERATING | L27: 2632 | M27: 2958465 | N27: 46023 | O27: 1982808960 | P27: NV | Q27: =VLOOKUP(E39841,Sheet3!A:B,2,FALSE)
A28: Ryan | B28: P | C28: Finnan | D28: 9477546 | E28: PH | F28: A | G28: 45891 | H28: AHP | I28: 156,156,1557,1557,1558,1558,1559,1559,3265,3265,3418,3418,3535,4144,4148,8232 | J28: KY | K28: STATE MEDICAL | L28: 50997 | M28: 2958465 | N28: 46081 | O28: 1366576233 | P28: KY,OH | Q28: =VLOOKUP(E53716,Sheet3!A:B,2,FALSE)
A29: James | B29: J | C29: Zubernis | D29: 4474124 | E29: PH | F29: A | G29: 45863 | H29: AHP | I29: 1993,4328,4329,11306,11307,11308 | J29: NV | K29: STATE MEDICAL | L29: DO3250 | M29: 2958465 | N29: 46022 | O29: 1609974385 | P29: NV | Q29: =VLOOKUP(E10599,Sheet3!A:B,2,FALSE)
A30: Andrea | C30: Blin | D30: 8291459 | E30: SW | F30: A | G30: 46049 | H30: ABH | I30: 24,60,75,221,243,389,638,1993,1995,2144,2158,2159,2408,3537,3670,3671,3779,3780,3781,4328,4329,4410,4411,9044,9063,9663,9691,9692,9693,11306,11307,11308 | J30: NV | K30: OPERATING | L30: 8882-C | M30: 2958465 | N30: 45747 | O30: 1477033082 | P30: IL,NV | Q30: =VLOOKUP(E39856,Sheet3!A:B,2,FALSE)
A31: Stephanie | B31: Lauren | C31: Feeney | D31: 5844861 | E31: SW | F31: A | G31: 45912 | H31: ABH | I31: 1993,8232,11306,11307,11308 | J31: NV | K31: OPERATING | L31: 7201-C | M31: 2958465 | N31: 46142 | O31: 1548618697 | P31: NV | Q31: =VLOOKUP(E17492,Sheet3!A:B,2,FALSE)
A32: Khai | B32: C. | C32: Truong | D32: 7616697 | E32: PH | F32: A | G32: 45996 | H32: AHP | I32: 1995,2158,2159,2408 | J32: KY | K32: STATE MEDICAL | L32: 39284 | M32: 2958465 | N32: 46082 | O32: 1003892548 | P32: NV | Q32: =VLOOKUP(E33882,Sheet3!A:B,2,FALSE)
A33: Hannah | B33: K. | C33: Sither | D33: 2600812 | E33: SW | F33: A | G33: 45961 | H33: ABH | I33: 21,156,433,511,1289,1558,1559,1737,1954,2249,2344,2772,2773,2774,3058,3535,4144,4148,8232 | J33: KY | K33: OPERATING | L33: 257611 | M33: 2958465 | N33: 46039 | O33: 1215728134 | P33: KY | Q33: =VLOOKUP(E4638,Sheet3!A:B,2,FALSE)
A34: James | B34: A. | C34: Bertone | D34: 7546171 | E34: SW | F34: A | G34: 46059 | H34: ABH | I34: 1993,8232,11306,11307,11308 | J34: NV | K34: OPERATING | L34: 2821-C | M34: 2958465 | N34: 46173 | O34: 1699870758 | P34: NV | Q34: =VLOOKUP(E33492,Sheet3!A:B,2,FALSE)
A35: Emily | B35: Mendaros | C35: Powers | D35: 5855955 | E35: SW | F35: A | G35: 46115 | H35: AHP | I35: 1993,1995,3058,8232,11306,11307,11308 | J35: NV | K35: OPERATING | L35: 6216-C | M35: 2958465 | N35: 46142 | O35: 1538355383 | P35: NV | Q35: =VLOOKUP(E17534,Sheet3!A:B,2,FALSE)
A36: Angela | C36: Mathew | D36: 7573385 | E36: MT | F36: A | G36: 45996 | H36: ABH | I36: 21,21,64,64,72,72,89,89,138,138,355,357,391,433,433,483,484,511,511,588,589,1289,1289,1300,1300,1301,1301,1344,1345,1737,1737,1751,1785,1954,1954,1960,1977,1993,1995,2104,2105,2106,2158,2159,2249,2249,2341,2341,2342,2342,2344,2344,2399,2399,2401,2401,2408,2475,2475,2772,2772,2773,2773,2774,2774,2833,2833,2846,3058,3058,3058,3058,3532,3532,3533,3533,3534,3534,3535,3535,3536,3536,3552,3552,3553,3553,3572,3572,3578,3610,3610,3670,3671,4144,4148,4328,4329,7864,7864,7865,7865,7866,7866,8232,8232,8232,8335,8335,8336,8336,8337,8337,8338,8338,8578,8578,8701,8701,9510,9510,9511,9511,9512,9512,9750,9750,11306,11307,11308 | J36: NV | K36: OPERATING | L36: 4700-R | M36: 2958465 | N36: 46023 | O36: 1144237868 | P36: IN,KS,KY,ME,NV,NY,UT | Q36: =VLOOKUP(E33643,Sheet3!A:B,2,FALSE)
A37: Amber | C37: Peace | D37: 6010588 | E37: PH | F37: A | G37: 46010 | H37: AHP | I37: 2772,2773,2774,4144,4148 | J37: KY | K37: STATE MEDICAL | L37: 04227 | M37: 2958465 | N37: 46081 | O37: 1902162167 | P37: KY | Q37: =VLOOKUP(E18213,Sheet3!A:B,2,FALSE)
A38: Leah | C38: Gardner | D38: 6079878 | E38: MT | F38: A | G38: 45912 | H38: ABH | I38: 1995,2158,2159,2408 | J38: NV | K38: OPERATING | L38: CP5050 | M38: 2958465 | N38: 46023 | O38: 1891210977 | P38: NV | Q38: =VLOOKUP(E19099,Sheet3!A:B,2,FALSE)
A39: Selin | C39: Santos | D39: 6568071 | E39: CP | F39: A | G39: 45877 | H39: ABH | I39: 24,25,33,35,41,47,54,65,66,67,74,86,94,98,102,109,110,133,136,143,147,199,221,227,233,243,244,257,338,345,385,386,387,394,396,397,399,402,407,411,437,445,447,448,449,454,482,604,606,612,631,638,640,641,1218,1219,1256,1291,1314,1352,1449,1450,1549,1561,1562,1564,1716,1830,1832,1890,1931,1939,1961,1962,1967,1968,1970,1975,1989,1990,2089,2111,2112,2156,2274,2275,2282,2283,2284,2285,2286,2521,2522,2530,2531,2570,2571,2572,2663,2841,3058,3058,3058,3196,3197,3198,3200,3201,3202,3214,3222,3237,3238,3239,3267,3395,3408,3411,3412,3413,3419,3536,3575,3891,3892,3893,3920,3998,3999,4000,4225,4226,4233,4234,4244,4477,4703,5240,5241,8232,8232,8232,8232,8232,8232,8232,8232,8298,8299,9166,13671,13672 | J39: NV | K39: OPERATING | L39: PSYPACT18696 | M39: 2958465 | N39: 46173 | O39: 1285163543 | P39: CO,CT,FL,IL,KS,NC,NJ,TX,VA,WA | Q39: =VLOOKUP(E24918,Sheet3!A:B,2,FALSE)
A40: Halley | C40: Stamm | D40: 8149941 | E40: LPC | F40: A | G40: 45912 | H40: AHP | I40: 73,156,511,582,1289,1465,1466,1558,1559,2249,2344,2772,2773,2774,3058 | J40: KY | K40: OPERATING | L40: 281763 | M40: 2958465 | N40: 46022 | O40: 1730667742 | P40: KY | Q40: =VLOOKUP(E37850,Sheet3!A:B,2,FALSE)
...
